Workbook

Sheet Roadmap
A1: Lot | B1: Feature | C1: Description | D1: Critères d'évaluation | E1: Dépendances | F1: Durée (j) | G1: Deadline | H1: Notes
A2: LOT 0 — FONDATIONS
A3: Lot 0 | B3: Création tickets backlog Lot 0 | C3: Découpage du Lot 0 en tickets détaillés avant le début du développement. | D3: - Tous les items du lot sont tracés en tickets - Critères d'acceptance rédigés - Prêts à être pris en sprint | E3: — | F3: 1 | G3: 05/06/2026 | H3: Règle : 1j en début de chaque lot
A4: Lot 0 | B4: Setup projet Symfony 7 + Docker Swarm | C4: Initialisation du projet Symfony 7 from scratch. Reprise de la stack Docker Swarm du Tage blanc (éprouvée sur charge). Configuration des volumes persistants, réseaux, secrets, déploiement Scaleway. | D4: - Projet Symfony 7 fonctionnel en local via docker-compose - Déploiement Scaleway via Docker Swarm - Volumes persistants OK - Healthchecks configurés | E4: — | F4: 2 | G4: 05/06/2026 | H4: Reprise stack Tage blanc
A5: Lot 0 | B5: GitLab Runner + pipelines CI/CD | C5: Pipelines build / test / deploy staging + prod. Cache composer et yarn. Déploiement automatique sur push main/staging. | D5: - Push main = déploiement prod - Push staging = déploiement staging - Cache composer/yarn actif - Tests lancés automatiquement | E5: Setup projet | F5: 2 | G5: 05/06/2026
A6: Lot 0 | B6: Schema BDD complet + migrations + seeders | C6: Design du schéma complet (~30 tables). Migrations Doctrine, index, contraintes FK. Seeders dev pour test. | D6: - ~30 tables créées via migrations - Relations et index en place - Seeders dev opérationnels - Doctrine génère le schéma sans erreur | E6: Setup projet | F6: 1.5 | G6: 05/06/2026
A7: Lot 0 | B7: Intégration Mux | C7: Signed playback tokens, upload direct depuis l'admin, webhooks asset ready. Gestion des IDs (asset_id, playback_id, upload_id). | D7: - Upload direct admin fonctionnel - Signed playback sur le front - Webhook asset.ready traité | E7: Schema BDD | F7: 0.5 | G7: 05/06/2026
A8: Lot 0 | B8: Sentry monitoring | C8: Installation bundle Sentry, configuration DSN, projet dédié V3, intégration exceptions handlers, traces de performance. | D8: - Erreurs remontent dans Sentry - Projet V3 dédié - Trace performance sur routes principales | E8: Setup projet | F8: 0.5 | G8: 05/06/2026
A9: Lot 0 | B9: Auth complète | C9: Inscription + vérification email (VerifyEmailBundle), login/logout, remember me 1 an via CacheRememberMeTokenProvider, reset password, session token unique (anti multi-connexions), firewall Symfony Security, voters. | D9: - Inscription + vérif email OK - Login/logout fonctionnel - Remember me 1 an actif - Reset password opérationnel - Session token unique empêche multi-connexions | E9: Schema BDD | F9: 2 | G9: 05/06/2026
A10: Lot 0 | B10: Modèle de données abonnement + codes promo | C10: Entités Doctrine (Subscription, PromoCode, SubscriptionHistory) avec états (active, paused, expired, canceled). Codes promo : type fixed/percentage, conditions de validité, compteur usage, création/gestion admin. Application au checkout Stripe avec traçage. | D10: - Entités créées avec transitions d'état - Codes promo admin CRUD complet - Application checkout Stripe tracée - Historique consolidé | E10: Schema BDD | F10: 2 | G10: 05/06/2026 | H10: Repensé vs V1
A11: Lot 0 | B11: Anti-chevauchement d'abonnements | C11: Un seul abo écrit actif à la fois, un seul oral, un seul dossier. Validation à la souscription (checkout Stripe), blocage avec message clair si conflit. Cas edge : renouvellement anticipé, upgrade mid-période. | D11: - Validation bloque souscription si conflit - Message clair user - Cas renouvellement/upgrade gérés | E11: Modèle abo | F11: 1 | G11: 05/06/2026
A12: Lot 0 | B12: Upgrade / downgrade / pause / reprise | C12: Transitions d'état cohérentes, gestion du prorata via Stripe, conservation de l'historique. UX user minimaliste (page paramètres → bouton). | D12: - Upgrade/downgrade avec prorata Stripe - Pause/reprise fonctionnelle - Historique conservé | E12: Anti-chevauchement | F12: 0.5 | G12: 05/06/2026
A13: Lot 0 | B13: CRUD users + reset password + alertes admin | C13: Liste paginée + recherche, édition profil, reset password avec génération + email, alertes (multi-connexions, discount_counter > 80, export CSV connexions). | D13: - Liste paginée fonctionnelle - Reset password avec email - Alertes multi-connexions remontées - Export CSV disponible | E13: Auth | F13: 0.25 | G13: 05/06/2026 | H13: CRUD simple
A14: Lot 0 | B14: CRUD catégories + sous-catégories | C14: Les 6 sections du TageMage + section Stratégie. Reorder, visibilité, thematic slug. Sous-catégories rattachées. | D14: - 6 sections + Stratégie créées - Reorder fonctionnel - Slugs uniques | E14: Schema BDD | F14: 0.25 | G14: 05/06/2026 | H14: CRUD simple
A15: Lot 0 | B15: CRUD cours avec CKEditor + upload Mux | C15: Titre, contenu CKEditor, vidéo Mux via upload direct, difficulté, visibilité publique, rattachement catégorie/sous-catégorie. Reorder par position. | D15: - Création cours avec vidéo uploadée sur Mux - CKEditor fonctionnel - Reorder par position - Rattachement catégories | E15: Mux + CRUD catégories | F15: 0.5 | G15: 05/06/2026 | H15: CRUD simple
A16: Lot 0 | B16: CRUD exercices + reorder drag&drop | C16: Liste filtrée par catégorie, drag&drop de l'ordre, rattachement cours/catégorie, type (tagemage_type ou cours). | D16: - Liste filtrée par catégorie - Drag&drop opérationnel - Types distincts | E16: CRUD catégories | F16: 0.25 | G16: 05/06/2026 | H16: CRUD simple
A17: Lot 0 | B17: CRUD questions d'exercice | C17: 5 réponses + bonne réponse, titre public, titre interne, correction texte + vidéo Mux liée, flag thème (micro-compétence), flag difficulté. | D17: - 5 réponses + bonne réponse OK - Correction texte + vidéo - Flag thème et difficulté | E17: CRUD exercices + Mux | F17: 0.25 | G17: 05/06/2026 | H17: CRUD simple
A18: Lot 0 | B18: CRUD TageMage + questions | C18: TageMage blanc (classique ou mensuel), liste de questions rattachées, type de sous-test, ordre. | D18: - TageMage classique et mensuel - Questions rattachées par type de sous-test - Ordre défini | E18: CRUD questions | F18: 0.5 | G18: 05/06/2026
A19: Lot 0 | B19: CRUD parcours + parties + items pondérés | C19: Structure hiérarchique (Parcours → Parts → Items), poids horaire sur chaque item, liens vers cours/exos/TageMage/flashcards/calcul/lecture, duplication de parcours. Les 15 profils par tranche de 25 points. | D19: - Parcours → parts → items créable - Poids horaire par item - Duplication fonctionnelle - Liens vers tous types d'items | E19: CRUD cours+exos+TageMage+flashcards | F19: 0.5 | G19: 05/06/2026
A20: Lot 0 | B20: CRUD flashcards + groupes | C20: Groupes thématiques, cartes recto/verso, image optionnelle, rattachement sous-catégorie. | D20: - Groupes thématiques créables - Recto/verso + image - Rattachement sous-catégorie | E20: CRUD catégories | F20: 0.25 | G20: 05/06/2026 | H20: CRUD simple
A21: Lot 0 | B21: CRUD micro-compétences + drills + test positionnement | C21: 3 entités liées. Micro-compétences rattachées aux leçons. Drills (5 questions par leçon). Test de positionnement (12-15 questions avec mapping score → niveau). | D21: - Micro-compétences rattachées aux leçons - Drills 5 Q par leçon - Test positionnement fonctionnel | E21: CRUD cours | F21: 0.75 | G21: 05/06/2026
A22: Lot 0 | B22: Étude migration | C22: Audit du schéma actuel. Livrable : note de décision 'on migre / on ne migre pas / partiellement' par entité (users, cours, exos, questions, erreurs, parcours, abos). Dry run sur échantillon 100 users + 200 exos. | D22: - Note de décision livrée - Dry run testé sur échantillon - Plan de migration par entité | E22: Schema BDD | F22: 2 | G22: 05/06/2026 | H22: Conditionne le Lot 6
A23: Lot 0 | B23: Recette fin de Lot 0 | C23: Tests E2E : inscription/auth, admin fonctionnel sur tous les CRUDs, Grégoire peut saisir 1 cours + 1 exo + 1 TageMage en conditions réelles. Corrections critiques. | D23: - Inscription + auth OK - Tous les CRUDs admin testés - Saisie contenu réelle validée par Grégoire - 0 anomalie critique | E23: Tous items Lot 0 | F23: 1 | G23: 05/06/2026
A24: Total lot 0 | C24: =SUM(F2:F23) -> 19.5
A25: LOT 1 — MONÉTISATION & ENTRÉE
A26: Lot 1 | B26: Création tickets backlog Lot 1 | C26: Découpage du Lot 1 en tickets détaillés avant le début du développement. | D26: - Tous les items du lot sont tracés en tickets - Critères d'acceptance rédigés | E26: Fin Lot 0 | F26: 1 | G26: 19/06/2026
A27: Lot 1 | B27: Onboarding pré-paiement multi-étapes | C27: Flux en 4 étapes : email+mdp, prénom+nom, école visée + date passage TM + niveau auto-évalué + heures dispo, récap. Barre de progression, validations, responsive, redirection paywall. | D27: - 4 étapes fonctionnelles - Barre de progression - Validations email et date - Responsive - Redirection paywall en fin | E27: Auth | F27: 0.5 | G27: 19/06/2026
A28: Lot 1 | B28: Témoignages page de paiement | C28: Intégration témoignages sur la page pricing + checkout Stripe, en rotation. Simple affichage. | D28: - Témoignages affichés en rotation - Présents sur pricing ET checkout | E28: Onboarding pré-paiement | F28: 0.25 | G28: 19/06/2026
A29: Lot 1 | B29: Plans Stripe + checkout + webhooks | C29: Page pricing avec 3 plans (Flex 87€, Optimal 219€, Premium). Checkout Stripe, succès et cancel URLs. Webhooks : invoice.payment_succeeded, customer.subscription.deleted, idempotence. Branché sur système abo Lot 0. | D29: - 3 plans affichés - Checkout Stripe fonctionnel - Webhooks idempotents - Abonnement activé après paiement | E29: Modèle abo | F29: 1 | G29: 19/06/2026
A30: Lot 1 | B30: Onboarding post-paiement | C30: Vidéo bienvenue formateurs, test positionnement (12-15 questions, 3 par domaine, scores affichés, sauvegarde), écran CTA Discord avec lien externe, premier exercice 5 questions selon faiblesses, correction placeholder, redirection dashboard. | D30: - Vidéo bienvenue affichée - Test positionnement 12-15 Q - Scores par domaine sauvegardés - CTA Discord - Premier exo généré | E30: Checkout + CRUD test positionnement | F30: 1 | G30: 19/06/2026
A31: Lot 1 | B31: Freemium avec cadenas conditionnels | C31: User non-abonné = 1 cours / 1 exo / 1 TageMage gratuits identifiés en admin. Cadenas visuel sur tous les autres contenus, clic → redirection paywall. Twig helper réutilisable. | D31: - 1 cours/1 exo/1 TM gratuits accessibles - Cadenas sur autres contenus - Clic cadenas → paywall | E31: Checkout | F31: 0.25 | G31: 19/06/2026
A32: Lot 1 | B32: Dashboard minimal placeholder | C32: Version simplifiée avec blocs disponibles en Lot 1 (placeholders pour parcours/stats qui viendront Lot 3). Liens vers cours/exos/TM/profil/paramètres. | D32: - Accessible après onboarding - Liens navigation principaux - Remplacé en Lot 3 | E32: Freemium | F32: 0.25 | G32: 19/06/2026 | H32: Remplacé au Lot 3
A33: Lot 1 | B33: Parrainage | C33: Génération code unique par user, dashboard parrainage, reward 10€ via Stripe Customer Balance, promo code -15% Stripe auto-attribué au filleul. | D33: - Code unique par user - Dashboard filleuls validés/en attente - Reward 10€ à validation - Promo -15% filleul | E33: Modèle abo | F33: 0.5 | G33: 19/06/2026 | H33: Reprise logique existante
A34: Lot 1 | B34: Écoles partenaires | C34: Matching automatique par domaine email à la vérification, application du crédit Stripe, notification user. | D34: - Matching auto à vérif email - Crédit Stripe appliqué - Notification user envoyée | E34: Auth + Stripe | F34: 0.5 | G34: 19/06/2026 | H34: Reprise logique existante
A35: Lot 1 | B35: Intégrations Brevo + Attio | C35: Brevo : templates emails transactionnels (bienvenue, vérif, reset, confirmation, rappel) via Symfony Mailer. Attio : commande app:attio:sync pour remonter users + abonnements. | D35: - Templates Brevo connectés - app:attio:sync fonctionnel - Emails transactionnels envoyés | E35: Auth + Checkout | F35: 0.5 | G35: 19/06/2026
A36: Lot 1 | B36: Recette fin de Lot 1 | C36: Tests E2E : visiteur → inscription → paywall → paiement → onboarding → dashboard → payant/freemium. Parrainage bout en bout. Corrections. | D36: - Tunnel monétisation E2E OK - Payant et freemium testés - Parrainage E2E - 0 anomalie critique | E36: Tous items Lot 1 | F36: 1 | G36: 19/06/2026
A37: Total lot 1 | C37: =SUM(F26:F36) -> 6.75
A38: LOT 2 — CŒUR D'APPRENTISSAGE + TAGEMAGE
A39: Lot 2 | B39: Création tickets backlog Lot 2 | C39: Découpage du Lot 2 en tickets détaillés. | D39: - Tous les items tracés en tickets - Critères d'acceptance rédigés | E39: Fin Lot 1 | F39: 1 | G39: 03/07/2026
A40: Lot 2 | B40: Bibliothèque de cours — catalogue | C40: Nav horizontale 6 sections TageMage + section Stratégie, accordéon chapitres, leçons dépliables, trait animé au scroll. Icônes + couleurs par section. | D40: - 6 sections + Stratégie affichées - Accordéon fonctionnel - Trait animé au scroll - Icônes + couleurs par section | E40: CRUD cours | F40: 0.5 | G40: 03/07/2026
...

Sheet Vue par lot
A1: Lot | B1: Nom | C1: Nb items | D1: Durée (j) | E1: Durée (sem) | F1: Fin prévue | G1: Features critiques | H1: Condition de sortie
A2: Lot 0 | B2: Fondations | C2: =IFERROR(__xludf.DUMMYFUNCTION("COUNTUNIQUE(Roadmap!B3:B23)"),21.0) -> 21 | D2: =Roadmap!C24 -> 19.5 | E2: 3.6 | F2: 05/06/2026 | G2: Setup + BDD + Auth + Abonnements + Admin complet | H2: Grégoire peut saisir du contenu, user test peut s'inscrire
A3: Lot 1 | B3: Monétisation & entrée | C3: =IFERROR(__xludf.DUMMYFUNCTION("COUNTUNIQUE(Roadmap!B26:B36)"),11.0) -> 11 | D3: =Roadmap!C37 -> 6.75 | E3: 1.4 | F3: 19/06/2026 | G3: Onboarding + Stripe + Freemium + Parrainage + Écoles + Discord sync | H3: Tunnel visiteur → payant → onboardé E2E
A4: Lot 2 | B4: Cœur + TageMage | C4: =IFERROR(__xludf.DUMMYFUNCTION("COUNTUNIQUE(Roadmap!B39:B53)"),15.0) -> 15 | D4: =Roadmap!C54 -> 13 | E4: 2.7 | F4: 03/07/2026 | G4: QuizInterface + CorrectionView + Carnet + Générateur + TageMage blanc | H4: Boucle cours→drill→exo→correction→entraînement ciblé
A5: Lot 3 | B5: Intelligence & progression | C5: =IFERROR(__xludf.DUMMYFUNCTION("COUNTUNIQUE(Roadmap!B56:B61)"),6.0) -> 6 | D5: =Roadmap!C62 -> 6 | E5: 1.2 | F5: 17/07/2026 | G5: Parcours adaptatif + Stats V2 + Dashboard bento | H5: Marie voit sa prochaine action et sa progression
A6: Lot 4 | B6: Outils & communauté | C6: =IFERROR(__xludf.DUMMYFUNCTION("COUNTUNIQUE(Roadmap!B64:B71)"),8.0) -> 8 | D6: =Roadmap!C72 -> 5.5 | E6: 1.2 | F6: 24/07/2026 | G6: Flashcards + Calcul mental + Lecture alpha + PDF + Discord | H6: Outils périphériques + interaction communautaire
A7: Lot 5 | B7: Gamification & finition | C7: =IFERROR(__xludf.DUMMYFUNCTION("COUNTUNIQUE(Roadmap!B74:B78)"),5.0) -> 5 | D7: =Roadmap!C79 -> 4 | E7: 0.7 | F7: 31/07/2026 | G7: Célébrations + Notifications + Paramètres + FAQ | H7: Effet WOW + récap expérience utilisateur
A8: Lot 6 | B8: Migration & go-live | C8: =IFERROR(__xludf.DUMMYFUNCTION("COUNTUNIQUE(Roadmap!B81:B85)"),5.0) -> 5 | D8: =Roadmap!C86 -> 8.5 | E8: 1.7 | F8: 07/08/2026 | G8: Scripts migration + Sync intégrations + Recette finale | H8: 0 anomalie critique/majeure, go-live
A9: TOTAL | C9: =SUM(C2:C8) -> 71 | D9: =SUM(D2:D8) -> 63.25 | E9: =SUM(E2:E8) -> 12.5
A10: BUFFER 10% | D10: =ROUND(D9*0.1,2) -> 6.33 | E10: =ROUND(D10/5,1) -> 1.3
A11: TOTAL V1 AVEC BUFFER | D11: =D9+D10 -> 69.58 | E11: =ROUND(D11/5,1) -> 13.9

Sheet Options
A1: Option | B1: Nom | C1: Description | D1: Durée (j) | E1: Condition d'activation | F1: Décision à prendre
A2: Option A | B2: API mobile | C2: Endpoints auth (Bearer), /api/flashcards, /api/calcul-mental, /api/lecture-alphabetique, /api/courses avec Mux signé, /api/completions sauvegarde vue de cours. Documentation OpenAPI + environnement test dev mobile. Scope : cours + flashcards + calcul + lecture (pas exos/sous-tests/TM). | D2: 3 | E2: Choix de faire l'app native (dev séparé) | F2: Fin Lot 4 / début Lot 5
A3: Option A | B3: App Mobile | C3: App mobile basique pour les mini jeux, la consultation des cours | D3: 5~10 | E3: Choix de faire l'app native (dev séparé) | F3: Fin Lot 4 / début Lot 5
A4: Option B | B4: PWA complète | C4: Manifest + service worker avancé. Cache management (cours cache-first, sous-tests network-first, carnet background-sync). Mode offline consultation. Splash screen. Installable iOS Safari + Android Chrome. Lighthouse PWA > 90. | D4: 5 | E4: Choix de la PWA comme solution mobile | F4: Fin Lot 4 / début Lot 5
A5: ⚠️ Options exclusives : on active l'une OU l'autre, pas les deux.

Sheet Timeline
A1: Semaine | B1: Dates | C1: Lot en cours | D1: Jalons / Livrables
A2: S1 | B2: 11/05 → 15/05 | C2: Lot 0 — Fondations
A3: S2 | B3: 18/05 → 22/05 | C3: Lot 0 — Fondations
A4: S3 | B4: 25/05 → 29/05 | C4: Lot 0 — Fondations
A5: S4 | B5: 01/06 → 05/06 | C5: Lot 0 — Fondations | D5: ✓ Fin Lot 0 — Recette + livraison
A6: S5 | B6: 08/06 → 12/06 | C6: Lot 1 — Monétisation | D6: ✓ Fin Lot 1 — Recette + livraison
A7: S6 | B7: 15/06 → 19/06 | C7: Lot 2 — Cœur + TM
A8: S7 | B8: 22/06 → 26/06 | C8: Lot 2 — Cœur + TM
A9: S8 | B9: 29/06 → 03/07 | C9: Lot 2 — Cœur + TM | D9: ✓ Fin Lot 2 — Recette + livraison
A10: S9 | B10: 06/07 → 10/07 | C10: Lot 3 — Intelligence | D10: ✓ Fin Lot 3 — Recette + livraison
A11: S10 | B11: 13/07 → 17/07 | C11: Lot 4 — Outils
A12: S11 | B12: 20/07 → 24/07 | C12: Lot 4 — Outils | D12: ✓ Fin Lot 4 — Recette + livraison
A13: S12 | B13: 27/07 → 31/07 | C13: Lot 6 — Migration
A14: S13 | B14: 03/08 → 07/08 | C14: Lot 6 — Migration | D14: ✓ Fin Lot 6 — Recette + livraison
A15: S14 | B15: 10/08 → 14/08 | C15: Buffer / marge | D15: Tampon global 10%

Sheet Contenu Grégoire
A1: Livrable | B1: Description | C1: Quantité | D1: Deadline | E1: Lot utilisateur | F1: Notes
A2: Micro-compétences + capsules vidéo | B2: Découpage du TageMage en 100 micro-compétences. Enregistrement des capsules vidéo courtes. | C2: ~100 | D2: 05/06/2026 | E2: Lot 2 | F2: Saisie admin dispo fin Lot 0
A3: Test de positionnement | B3: 12-15 questions mappées aux micro-compétences. Scoring par domaine. | C3: 12-15 Q | D3: 05/06/2026 | E3: Lot 1
A4: Drills par leçon | B4: 5 questions simples post-vidéo par leçon pour valider la compréhension immédiate. | C4: ~500 Q (100 leçons × 5) | D4: 05/06/2026 | E4: Lot 2 | F4: Pas de correction vidéo nécessaire
A5: 15 profils de parcours | B5: Découpage des items pondérés en heures par tranche de 25 points de score. Total d'heures à faire par profil. | C5: 15 profils | D5: 03/07/2026 | E5: Lot 3 | F5: Dépend des items créés au Lot 2
A6: Catégorisations d'erreur | B6: Liste des raisons d'erreur à proposer à l'élève (manque de temps, mauvaise lecture, etc.). | C6: ~8-10 catégories | D6: 19/06/2026 | E6: Lot 2
A7: Moyennes ASTPrep par sous-test | B7: Calcul des moyennes historiques par sous-test pour affichage sur les cards catalogue. | C7: 6 moyennes | D7: 19/06/2026 | E7: Lot 2 | F7: Données extraites de la prod actuelle
A8: Corrections vidéo questions | B8: Vidéos de correction par question d'exercice (existant + nouveau contenu). | C8: Variable | D8: 03/07/2026 | E8: Lot 2 | F8: Chargement à la demande pour coût Mux
A9: Fiches PDF récap | B9: Fiches téléchargeables (formules, tables, astuces CM, etc.). | C9: ~20-30 fiches | D9: 17/07/2026 | E9: Lot 4
